ERROR:    Exception in ASGI application
Traceback (most recent call last):
  File "D:\work\pythonProject\inventory_final\venv\lib\site-packages\sqlalchemy\orm\mapper.py", line 2053, in get_property
    return self._props[key]
KeyError: 'orders'

The above exception was the direct cause of the following exception:

Traceback (most recent call last):
  File "D:\work\pythonProject\inventory_final\venv\lib\site-packages\uvicorn\protocols\http\h11_impl.py", line 407, in run_asgi
    result = await app(  # type: ignore[func-returns-value]
  File "D:\work\pythonProject\inventory_final\venv\lib\site-packages\uvicorn\middleware\proxy_headers.py", line 78, in __call__
    return await self.app(scope, receive, send)
  File "D:\work\pythonProject\inventory_final\venv\lib\site-packages\fastapi\applications.py", line 270, in __call__
    await super().__call__(scope, receive, send)
  File "D:\work\pythonProject\inventory_final\venv\lib\site-packages\starlette\applications.py", line 124, in __call__
    await self.middleware_stack(scope, receive, send)
  File "D:\work\pythonProject\inventory_final\venv\lib\site-packages\starlette\middleware\errors.py", line 184, in __call__
    raise exc
  File "D:\work\pythonProject\inventory_final\venv\lib\site-packages\starlette\middleware\errors.py", line 162, in __call__
    await self.app(scope, receive, _send)
  File "D:\work\pythonProject\inventory_final\venv\lib\site-packages\starlette\middleware\exceptions.py", line 79, in __call__
    raise exc
  File "D:\work\pythonProject\inventory_final\venv\lib\site-packages\starlette\middleware\exceptions.py", line 68, in __call__
    await self.app(scope, receive, sender)
  File "D:\work\pythonProject\inventory_final\venv\lib\site-packages\fastapi\middleware\asyncexitstack.py", line 21, in __call__
    raise e
  File "D:\work\pythonProject\inventory_final\venv\lib\site-packages\fastapi\middleware\asyncexitstack.py", line 18, in __call__
    await self.app(scope, receive, send)
  File "D:\work\pythonProject\inventory_final\venv\lib\site-packages\starlette\routing.py", line 706, in __call__
    await route.handle(scope, receive, send)
  File "D:\work\pythonProject\inventory_final\venv\lib\site-packages\starlette\routing.py", line 276, in handle
    await self.app(scope, receive, send)
  File "D:\work\pythonProject\inventory_final\venv\lib\site-packages\starlette\routing.py", line 66, in app
    response = await func(request)
  File "D:\work\pythonProject\inventory_final\venv\lib\site-packages\fastapi\routing.py", line 235, in app
    raw_response = await run_endpoint_function(
  File "D:\work\pythonProject\inventory_final\venv\lib\site-packages\fastapi\routing.py", line 163, in run_endpoint_function
    return await run_in_threadpool(dependant.call, **values)
  File "D:\work\pythonProject\inventory_final\venv\lib\site-packages\starlette\concurrency.py", line 41, in run_in_threadpool
    return await anyio.to_thread.run_sync(func, *args)
  File "D:\work\pythonProject\inventory_final\venv\lib\site-packages\anyio\to_thread.py", line 31, in run_sync
    return await get_asynclib().run_sync_in_worker_thread(
  File "D:\work\pythonProject\inventory_final\venv\lib\site-packages\anyio\_backends\_asyncio.py", line 937, in run_sync_in_worker_thread
    return await future
  File "D:\work\pythonProject\inventory_final\venv\lib\site-packages\anyio\_backends\_asyncio.py", line 867, in run
    result = context.run(func, *args)
  File "D:\work\pythonProject\inventory_final\.\webapps\routers\items.py", line 47, in item_home
    items = db.query(Item).all()
  File "D:\work\pythonProject\inventory_final\venv\lib\site-packages\sqlalchemy\orm\session.py", line 2161, in query
    return self._query_cls(entities, self, **kwargs)
  File "D:\work\pythonProject\inventory_final\venv\lib\site-packages\sqlalchemy\orm\query.py", line 180, in __init__
    self._set_entities(entities)
  File "D:\work\pythonProject\inventory_final\venv\lib\site-packages\sqlalchemy\orm\query.py", line 187, in _set_entities
    self._raw_columns = [
  File "D:\work\pythonProject\inventory_final\venv\lib\site-packages\sqlalchemy\orm\query.py", line 188, in <listcomp>
    coercions.expect(
  File "D:\work\pythonProject\inventory_final\venv\lib\site-packages\sqlalchemy\sql\coercions.py", line 181, in expect
    insp._post_inspect
  File "D:\work\pythonProject\inventory_final\venv\lib\site-packages\sqlalchemy\util\langhelpers.py", line 1184, in __get__
    obj.__dict__[self.__name__] = result = self.fget(obj)
  File "D:\work\pythonProject\inventory_final\venv\lib\site-packages\sqlalchemy\orm\mapper.py", line 2199, in _post_inspect
    self._check_configure()
  File "D:\work\pythonProject\inventory_final\venv\lib\site-packages\sqlalchemy\orm\mapper.py", line 1941, in _check_configure
    _configure_registries({self.registry}, cascade=True)
  File "D:\work\pythonProject\inventory_final\venv\lib\site-packages\sqlalchemy\orm\mapper.py", line 3527, in _configure_registries
    _do_configure_registries(registries, cascade)
  File "D:\work\pythonProject\inventory_final\venv\lib\site-packages\sqlalchemy\orm\mapper.py", line 3566, in _do_configure_registries
    mapper._post_configure_properties()
  File "D:\work\pythonProject\inventory_final\venv\lib\site-packages\sqlalchemy\orm\mapper.py", line 1958, in _post_configure_properties
    prop.init()
  File "D:\work\pythonProject\inventory_final\venv\lib\site-packages\sqlalchemy\orm\interfaces.py", line 231, in init
    self.do_init()
  File "D:\work\pythonProject\inventory_final\venv\lib\site-packages\sqlalchemy\orm\relationships.py", line 2150, in do_init
    self._generate_backref()
  File "D:\work\pythonProject\inventory_final\venv\lib\site-packages\sqlalchemy\orm\relationships.py", line 2486, in _generate_backref
    self._add_reverse_property(self.back_populates)
  File "D:\work\pythonProject\inventory_final\venv\lib\site-packages\sqlalchemy\orm\relationships.py", line 2056, in _add_reverse_property
    other = self.mapper.get_property(key, _configure_mappers=False)
  File "D:\work\pythonProject\inventory_final\venv\lib\site-packages\sqlalchemy\orm\mapper.py", line 2055, in get_property
    util.raise_(
  File "D:\work\pythonProject\inventory_final\venv\lib\site-packages\sqlalchemy\util\compat.py", line 210, in raise_
    raise exception
sqlalchemy.exc.InvalidRequestError: Mapper 'mapped class User->user' has no property 'orders'
